══════════════════════ Running solver against test cases ══════════════════════
=> fup_001 tests:07 sources:[cases.tio(07)] solvers:[solver.cpp][ ϵ ω ω ϵ ω ω ϵ ]
(ϵ execut_error)[00] GR:014 cases.tio (duas raízes) 
(ω wrong_output)[01] GR:014 cases.tio (duas raízes) 
(ω wrong_output)[02] GR:014 cases.tio (uma raiz   ) 
(ϵ execut_error)[03] GR:014 cases.tio (sem raízes ) 
(ω wrong_output)[04] GR:014 cases.tio (05         ) 
(ω wrong_output)[05] GR:014 cases.tio (06         ) 
(ϵ execut_error)[06] GR:014 cases.tio (07         ) 
╭──────────────────────────────────────────────────────────────────────────────
│             (ϵ execut_error)[00] GR:014 cases.tio (duas raízes)              
├─────────────────────────────────── INPUT ────────────────────────────────────
├────────────────────────────────── EXPECTED ──────────────────────────────────
≠ 0.44
≠ -5.07
├────────────────────────────────── RECEIVED ──────────────────────────────────
≠ terminate called after throwing an instance of 'std::invalid_argument'
≠   what():  Impossivel calcular
├────────────────────────────────── MISMATCH ──────────────────────────────────
│ 0.44↵                                                                   (expected)
│ terminate⸱called⸱after⸱throwing⸱an⸱instance⸱of⸱'std::invalid_argument'↵ (received)
│ ↑                                                                       (mismatch)
╰──────────────────────────────────────────────────────────────────────────────

