══════════════════════ Running solver against test cases ══════════════════════
=> fup_001 tests:07 sources:[cases.tio(07)] solvers:[solver.py][ ϵ ω ω ✓ ω ω ✓ ]
(ϵ execut_error)[00] GR:014 cases.tio (duas raízes) 
(ω wrong_output)[01] GR:014 cases.tio (duas raízes) 
(ω wrong_output)[02] GR:014 cases.tio (uma raiz   ) 
(✓ correct_case)[03] GR:014 cases.tio (sem raízes ) 
(ω wrong_output)[04] GR:014 cases.tio (05         ) 
(ω wrong_output)[05] GR:014 cases.tio (06         ) 
(✓ correct_case)[06] GR:014 cases.tio (07         ) 
╭──────────────────────────────────────────────────────────────────────────────
│             (ϵ execut_error)[00] GR:014 cases.tio (duas raízes)              
├─────────────────────────────────── INPUT ────────────────────────────────────
├────────────────────────────────── EXPECTED ──────────────────────────────────
╪ 0.44
╪ -5.07
╪ 
╪ 
╪ 
├────────────────────────────────── RECEIVED ──────────────────────────────────
╪ Traceback (most recent call last):
╪   File "/home/lion/Dropbox/gits/tools/tko/ihc_tests/03_run/fup_001/./solver.py", line 1, in <module>
╪     a = float(input())
╪               ^^^^^^^
╪ EOFError: EOF when reading a line
├────────────────────────────────── MISMATCH ──────────────────────────────────
│ 0.44↵                               (expected)
│ Traceback⸱(most⸱recent⸱call⸱last):↵ (received)
│ ↑                                   (mismatch)
╰──────────────────────────────────────────────────────────────────────────────

